<?xml version='1.0'?>
<sdf version='1.4'>
  <model name="Coaster">
    <static>false</static>
<!-- LINKS -->
    <link name='deck'>
      <pose>0 0 .080 0 0 0</pose>

      <collision name='collision'>
        <geometry>
          <box>
            <size>.777 .185 .05</size>
          </box>
        </geometry>
      </collision>

      <visual name='visual'>
        <geometry>
          <mesh>
            <uri>model://coaster/meshes/skateboard_mesh.dae</uri>
          </mesh>
        </geometry>
      </visual>

      <collision name='right_caster_collision'>
        <pose>0.225 -0.075 -0.050 0 0 0</pose>
        <geometry>
            <sphere>
            <radius>.025</radius>
          </sphere>
        </geometry>

        <surface>
          <friction>
            <ode>
              <mu>0</mu>
              <mu2>0</mu2>
              <slip1>1.0</slip1>
              <slip2>1.0</slip2>
            </ode>
          </friction>
        </surface>
      </collision>

      <!-- <visual name='right_caster_visual'>
        <pose>0.225 -0.075 -0.050 0 0 0</pose>
        <geometry>
          <sphere>
            <radius>.025</radius>
          </sphere>
        </geometry>
      </visual> -->

      <collision name='left_caster_collision'>
        <pose>0.225 0.075 -0.050 0 0 0</pose>
        <geometry>
            <sphere>
            <radius>.025</radius>
          </sphere>
        </geometry>

        <surface>
          <friction>
            <ode>
              <mu>0</mu>
              <mu2>0</mu2>
              <slip1>1.0</slip1>
              <slip2>1.0</slip2>
            </ode>
          </friction>
        </surface>
      </collision>

      <!-- <visual name='left_caster_visual'>
        <pose>0.225 0.075 -0.050 0 0 0</pose>
        <geometry>
          <sphere>
            <radius>.025</radius>
          </sphere>
        </geometry>
      </visual> -->
    </link>


<!-- 450 mm between wheels and 150 mm the other way -->
    <link name="left_wheel">
      <pose>-0.225 0.075 0.025 0 1.5707 1.5707</pose>
      <collision name="collision">
        <geometry>
          <cylinder>
            <radius>.025</radius>
            <length>.05</length>
          </cylinder>
        </geometry>
      </collision>
      <!-- <visual name="visual">
        <geometry>
          <cylinder>
            <radius>.025</radius>
            <length>.05</length>
          </cylinder>
        </geometry>
      </visual> -->
    </link>

    <link name="right_wheel">
      <pose>-0.225 -0.075 0.025 0 1.5707 1.5707</pose>
      <collision name="collision">
        <geometry>
          <cylinder>
            <radius>.025</radius>
            <length>.05</length>
          </cylinder>
        </geometry>
      </collision>
      <!-- <visual name="visual">
        <geometry>
          <cylinder>
            <radius>.025</radius>
            <length>.05</length>
          </cylinder>
        </geometry>
      </visual> -->
    </link>

<!-- JOINTS -->
    <joint type="revolute" name="left_wheel_hinge">
      <pose>0 0 -0.03 0 0 0</pose>
      <child>left_wheel</child>
      <parent>deck</parent>
      <axis>
        <xyz>0 1 0</xyz>
      </axis>
    </joint>

    <joint type="revolute" name="right_wheel_hinge">
      <pose>0 0 0.03 0 0 0</pose>
      <child>right_wheel</child>
      <parent>deck</parent>
      <axis>
        <xyz>0 1 0</xyz>
      </axis>
    </joint>
  </model>
</sdf>